<?xml version="1.0"?>
<sdf version="1.7">


    <model name="mini_robot">

        <frame name="lidar_frame" attached_to="base_link">
            <pose>0.8 0 0.5 0 0 0</pose>
        </frame>

        <!-- BASE LINK -->
        <link name="base_link">
            <pose relative_to="__model__">0.5 0 0.4 0 0 0</pose>
            <collision name="base_collision">
                <geometry>
                    <box>
                        <size>0.4 0.8 0.4</size>
                    </box>
                </geometry>
            </collision>
            <visual name="base_visual">
                <geometry>
                    <box>
                        <size>0.4 0.8 0.4</size>
                    </box>
                </geometry>
                <material>
                    <ambient>0.0 0.0 0.3 1</ambient>
                    <diffuse>0.0 0.0 0.4 1</diffuse>
                    <specular>0.1 0.1 0.3 1</specular>
                </material>
            </visual>
            <inertial>
                <inertia>
                        <ixx>0.095329</ixx>
                        <ixy>0</ixy>
                        <ixz>0</ixz>
                        <iyy>0.381317</iyy>
                        <iyz>0</iyz>
                        <izz>0.476646</izz>
                </inertia>
            </inertial>

        </link>

        <link name="base_to_left_wheel">
            <pose relative_to="base_link">0 0.4 0 0 0 0</pose>
            <visual name="base_to_left_wheel_visual">
                <geometry>
                    <box>
                        <size>0.1 0.1 0.1</size>
                    </box>
                </geometry>
                <material>
                    <ambient>0.05 0.05 0.05 1</ambient>
                    <diffuse>0.05 0.05 0.05 1</diffuse>
                    <specular>0.1 0.1 0.1 1</specular>
                </material>
            </visual>
            <collision name="base_to_left_wheel_collision">
                <geometry>
                    <box>
                        <size>0.1 0.1 0.1</size>
                    </box>
                </geometry>
            </collision>
            <inertial>
                <inertia>
                    <ixx>0.0001</ixx>
                    <ixy>0</ixy>
                    <ixz>0</ixz>
                    <iyy>0.0001</iyy>
                    <iyz>0</iyz>
                    <izz>0.0001</izz>
                </inertia>
            </inertial>
        </link>

        <link name="base_to_right_wheel">
            <pose relative_to="base_link">0 -0.4 0 0 0 0</pose>
            <visual name="base_to_right_wheel_visual">
                <geometry>
                    <box>
                        <size>0.1 0.1 0.1</size>
                    </box>
                </geometry>
                <material>
                    <ambient>0.05 0.05 0.05 1</ambient>
                    <diffuse>0.05 0.05 0.05 1</diffuse>
                    <specular>0.1 0.1 0.1 1</specular>
                </material>
            </visual>
            <collision name="base_to_right_wheel_collision">
                <geometry>
                    <box>
                        <size>0.1 0.1 0.1</size>
                    </box>
                </geometry>
            </collision>
            <inertial>
                <inertia>
                    <ixx>0.0001</ixx>
                    <ixy>0</ixy>
                    <ixz>0</ixz>
                    <iyy>0.0001</iyy>
                    <iyz>0</iyz>
                    <izz>0.0001</izz>
                </inertia>
            </inertial>
        </link>

        <!-- LEFT WHEELS -->
        <link name="left_wheel_link">
            <pose relative_to="base_link">0 0.6 0 -1.5707 0 0</pose>
            <collision name="left_wheel_collision">
                <geometry>
                    <cylinder>
                        <radius>0.4</radius>
                        <length>0.3</length>
                    </cylinder>
                </geometry>
            </collision>
            <visual name="left_wheel_visual">
                <geometry>
                    <cylinder>
                        <radius>0.4</radius>
                        <length>0.3</length>
                    </cylinder>
                </geometry>
                <material>
                    <ambient>0.05 0.05 0.05 1</ambient>
                    <diffuse>0.05 0.05 0.05 1</diffuse>
                    <specular>0.1 0.1 0.1 1</specular>
                </material>
            </visual>
            <inertial>
                <inertia>
                        <ixx>0.00125</ixx>
                        <ixy>0</ixy>
                        <ixz>0</ixz>
                        <iyy>0.00125</iyy>
                        <iyz>0</iyz>
                        <izz>0.0001</izz>
                </inertia>
            </inertial>
        </link>

        <!-- RIGHT WHEEL -->
        <link name="right_wheel_link">
            <pose relative_to="base_link">0 -0.6 0 -1.5707 0 0</pose>
            <collision name="right_wheel_collision">
                <geometry>
                    <cylinder>
                        <radius>0.4</radius>
                        <length>0.3</length>
                    </cylinder>
                </geometry>
            </collision>
            <visual name="right_wheel_visual">
                <geometry>
                    <cylinder>
                        <radius>0.4</radius>
                        <length>0.3</length>
                    </cylinder>
                </geometry>
                <material>
                    <ambient>0.05 0.05 0.05 1</ambient>
                    <diffuse>0.05 0.05 0.05 1</diffuse>
                    <specular>0.1 0.1 0.1 1</specular>
                </material>
            </visual>
            <inertial>
                <inertia>
                        <ixx>0.00125</ixx>
                        <ixy>0</ixy>
                        <ixz>0</ixz>
                        <iyy>0.00125</iyy>
                        <iyz>0</iyz>
                        <izz>0.0001</izz>
                </inertia>
            </inertial>
        </link>

        <link name="left_wheel_detail_link">
            <pose relative_to="base_link">0 0.75 0 -1.5707 0 0</pose>
            <collision name="left_wheel_detail_collision">
                <geometry>
                    <cylinder>
                        <radius>0.35</radius>
                        <length>0.1</length>
                    </cylinder>
                </geometry>
            </collision>
            <visual name="left_wheel_detail_visual">
                <geometry>
                    <cylinder>
                        <radius>0.35</radius>
                        <length>0.1</length>
                    </cylinder>
                </geometry>
                <material>
                    <ambient>0.05 0.05 0.05 1</ambient>
                    <diffuse>0.05 0.05 0.05 1</diffuse>
                    <specular>0.1 0.1 0.1 1</specular>
                </material>
            </visual>
            <inertial>
                <inertia>
                        <ixx>0.00125</ixx>
                        <ixy>0</ixy>
                        <ixz>0</ixz>
                        <iyy>0.00125</iyy>
                        <iyz>0</iyz>
                        <izz>0.0001</izz>
                </inertia>
            </inertial>
        </link>

        <link name="right_wheel_detail_link">
            <pose relative_to="base_link">0 -0.75 0 -1.5707 0 0</pose>
            <collision name="right_wheel_detail_collision">
                <geometry>
                    <cylinder>
                        <radius>0.35</radius>
                        <length>0.1</length>
                    </cylinder>
                </geometry>
            </collision>
            <visual name="right_wheel_detail_visual">
                <geometry>
                    <cylinder>
                        <radius>0.35</radius>
                        <length>0.1</length>
                    </cylinder>
                </geometry>
                <material>
                    <ambient>0.05 0.05 0.05 1</ambient>
                    <diffuse>0.05 0.05 0.05 1</diffuse>
                    <specular>0.1 0.1 0.1 1</specular>
                </material>
            </visual>
            <inertial>
                <inertia>
                        <ixx>0.00125</ixx>
                        <ixy>0</ixy>
                        <ixz>0</ixz>
                        <iyy>0.00125</iyy>
                        <iyz>0</iyz>
                        <izz>0.0001</izz>
                </inertia>
            </inertial>
        </link>

        <!-- JOINTS -->

        <joint name="base_to_left_wheel_joint" type="fixed">
            <pose relative_to="base_link"/>
            <parent>base_link</parent>
            <child>base_to_left_wheel</child>
        </joint>

        <joint name="base_to_right_wheel_joint" type="fixed">
            <pose relative_to="base_link"/>
            <parent>base_link</parent>
            <child>base_to_right_wheel</child>
        </joint>

        <joint name="left_wheel_joint" type="revolute">
            <pose relative_to="left_wheel_link"/>
            <parent>base_to_left_wheel</parent>
            <child>left_wheel_link</child>
            <axis>
                <xyz>0 0 1</xyz>
                <limit>
                    <lower>-1.79769e+308</lower>
                    <upper>1.79769e+308</upper>
                </limit>
            </axis>
        </joint>

        <joint name="right_wheel_joint" type="revolute">
            <pose relative_to="right_wheel_link"/>   
            <parent>base_to_right_wheel</parent>
            <child>right_wheel_link</child>
            <axis>
                <xyz>0 0 1</xyz>
                <limit>
                    <lower>-1.79769e+308</lower>
                    <upper>1.79769e+308</upper>
                </limit>
            </axis>
        </joint>

        <joint name="left_wheel_detail_joint" type="fixed">
            <pose relative_to="left_wheel_link"/>
            <parent>left_wheel_link</parent>
            <child>left_wheel_detail_link</child>
        </joint>

        <joint name="right_wheel_detail_joint" type="fixed">
            <pose relative_to="right_wheel_link"/>
            <parent>right_wheel_link</parent>
            <child>right_wheel_detail_link</child>
        </joint>

        <plugin 
            filename="libignition-gazebo-diff-drive-system.so"
            name="ignition::gazebo::systems::DiffDrive">
            <left_joint>left_wheel_joint</left_joint>
            <right_joint>right_wheel_joint</right_joint>
            <wheel_separation>1.2</wheel_separation>
            <wheel_radius>0.4</wheel_radius>
            <odom_publish_frequency>1</odom_publish_frequency>
            <topic>/cmd_vel</topic>
        </plugin>

        <!-- W = MOVE FORWARD -->
        <plugin filename="gz-sim-triggered-publisher-system" name="gz::sim::systems::TriggeredPublisher">
            <input type="gz.msgs.Int32" topic="/keyboard/keypress">
                <match field="data">87</match>
            </input>
            <output type="gz.msgs.Twist" topic="/cmd_vel">
                linear: {x: 2}, angular: {z: 0.0}
            </output>
        </plugin>

        <!-- S = MOVE BACKWARD -->

        <plugin filename="gz-sim-triggered-publisher-system" name="gz::sim::systems::TriggeredPublisher">
            <input type="gz.msgs.Int32" topic="/keyboard/keypress">
                <match field="data">83</match>
            </input>
            <output type="gz.msgs.Twist" topic="/cmd_vel">
                linear: {x: -2}, angular: {z: 0.0}
            </output>
        </plugin>

        <!-- A = TURN LEFT -->
        <plugin filename="gz-sim-triggered-publisher-system" name="gz::sim::systems::TriggeredPublisher">
            <input type="gz.msgs.Int32" topic="/keyboard/keypress">
                <match field="data">65</match>
            </input>
            <output type="gz.msgs.Twist" topic="/cmd_vel">
                linear: {x: 0.0}, angular: {z: 0.5}
            </output>
        </plugin>

        <!-- D = TURN RIGHT -->
        <plugin filename="gz-sim-triggered-publisher-system" name="gz::sim::systems::TriggeredPublisher">
            <input type="gz.msgs.Int32" topic="/keyboard/keypress">
            <match field="data">68</match>
            </input>
            <output type="gz.msgs.Twist" topic="/cmd_vel">
            linear: {x: 0.0}, angular: {z: -0.5}
            </output>
        </plugin>


    </model>
</sdf>
